Traceback (most recent call last):
  File "/mnt/home/rsilva/Documents/miniconda3/envs/datascience/lib/python3.12/site-packages/jupyter_cache/executors/utils.py", line 58, in single_nb_execution
    executenb(
  File "/mnt/home/rsilva/Documents/miniconda3/envs/datascience/lib/python3.12/site-packages/nbclient/client.py", line 1314, in execute
    return NotebookClient(nb=nb, resources=resources, km=km, **kwargs).execute()
           ^^^^^^^^^^^^^^^^^^^^^^^^^^^^^^^^^^^^^^^^^^^^^^^^^^^^^^^^^^^^^^^^^^^^^
  File "/mnt/home/rsilva/Documents/miniconda3/envs/datascience/lib/python3.12/site-packages/jupyter_core/utils/__init__.py", line 165, in wrapped
    return loop.run_until_complete(inner)
           ^^^^^^^^^^^^^^^^^^^^^^^^^^^^^^
  File "/mnt/home/rsilva/Documents/miniconda3/envs/datascience/lib/python3.12/asyncio/base_events.py", line 687, in run_until_complete
    return future.result()
           ^^^^^^^^^^^^^^^
  File "/mnt/home/rsilva/Documents/miniconda3/envs/datascience/lib/python3.12/site-packages/nbclient/client.py", line 709, in async_execute
    await self.async_execute_cell(
  File "/mnt/home/rsilva/Documents/miniconda3/envs/datascience/lib/python3.12/site-packages/nbclient/client.py", line 1062, in async_execute_cell
    await self._check_raise_for_error(cell, cell_index, exec_reply)
  File "/mnt/home/rsilva/Documents/miniconda3/envs/datascience/lib/python3.12/site-packages/nbclient/client.py", line 918, in _check_raise_for_error
    raise CellExecutionError.from_cell_and_msg(cell, exec_reply_content)
nbclient.exceptions.CellExecutionError: An error occurred while executing the following cell:
------------------
import plotly.express as px

fig = px.pie(pd.DataFrame(df.Toler.value_counts()).reset_index(),
             values='Toler', names='index')
fig.show()

------------------


[0;31m---------------------------------------------------------------------------[0m
[0;31mModuleNotFoundError[0m                       Traceback (most recent call last)
Cell [0;32mIn[10], line 1[0m
[0;32m----> 1[0m [38;5;28;01mimport[39;00m [38;5;21;01mplotly[39;00m[38;5;21;01m.[39;00m[38;5;21;01mexpress[39;00m [38;5;28;01mas[39;00m [38;5;21;01mpx[39;00m
[1;32m      3[0m fig [38;5;241m=[39m px[38;5;241m.[39mpie(pd[38;5;241m.[39mDataFrame(df[38;5;241m.[39mToler[38;5;241m.[39mvalue_counts())[38;5;241m.[39mreset_index(),
[1;32m      4[0m              values[38;5;241m=[39m[38;5;124m'[39m[38;5;124mToler[39m[38;5;124m'[39m, names[38;5;241m=[39m[38;5;124m'[39m[38;5;124mindex[39m[38;5;124m'[39m)
[1;32m      5[0m fig[38;5;241m.[39mshow()

[0;31mModuleNotFoundError[0m: No module named 'plotly'

