Traceback (most recent call last):
  File "/mnt/home/rsilva/Documents/miniconda3/envs/bioestats/lib/python3.9/site-packages/jupyter_cache/executors/utils.py", line 58, in single_nb_execution
    executenb(
  File "/mnt/home/rsilva/Documents/miniconda3/envs/bioestats/lib/python3.9/site-packages/nbclient/client.py", line 1314, in execute
    return NotebookClient(nb=nb, resources=resources, km=km, **kwargs).execute()
  File "/mnt/home/rsilva/Documents/miniconda3/envs/bioestats/lib/python3.9/site-packages/jupyter_core/utils/__init__.py", line 165, in wrapped
    return loop.run_until_complete(inner)
  File "/mnt/home/rsilva/Documents/miniconda3/envs/bioestats/lib/python3.9/asyncio/base_events.py", line 647, in run_until_complete
    return future.result()
  File "/mnt/home/rsilva/Documents/miniconda3/envs/bioestats/lib/python3.9/site-packages/nbclient/client.py", line 709, in async_execute
    await self.async_execute_cell(
  File "/mnt/home/rsilva/Documents/miniconda3/envs/bioestats/lib/python3.9/site-packages/nbclient/client.py", line 1062, in async_execute_cell
    await self._check_raise_for_error(cell, cell_index, exec_reply)
  File "/mnt/home/rsilva/Documents/miniconda3/envs/bioestats/lib/python3.9/site-packages/nbclient/client.py", line 918, in _check_raise_for_error
    raise CellExecutionError.from_cell_and_msg(cell, exec_reply_content)
nbclient.exceptions.CellExecutionError: An error occurred while executing the following cell:
------------------
scipy.mean(data)
------------------


[0;31m---------------------------------------------------------------------------[0m
[0;31mKeyError[0m                                  Traceback (most recent call last)
File [0;32m/mnt/home/rsilva/Documents/miniconda3/envs/bioestats/lib/python3.9/site-packages/scipy/__init__.py:137[0m, in [0;36m__getattr__[0;34m(name)[0m
[1;32m    136[0m [38;5;28;01mtry[39;00m:
[0;32m--> 137[0m     [38;5;28;01mreturn[39;00m [38;5;28;43mglobals[39;49m[43m([49m[43m)[49m[43m[[49m[43mname[49m[43m][49m
[1;32m    138[0m [38;5;28;01mexcept[39;00m [38;5;167;01mKeyError[39;00m:

[0;31mKeyError[0m: 'mean'

During handling of the above exception, another exception occurred:

[0;31mAttributeError[0m                            Traceback (most recent call last)
Cell [0;32mIn[3], line 1[0m
[0;32m----> 1[0m [43mscipy[49m[38;5;241;43m.[39;49m[43mmean[49m(data)

File [0;32m/mnt/home/rsilva/Documents/miniconda3/envs/bioestats/lib/python3.9/site-packages/scipy/__init__.py:139[0m, in [0;36m__getattr__[0;34m(name)[0m
[1;32m    137[0m     [38;5;28;01mreturn[39;00m [38;5;28mglobals[39m()[name]
[1;32m    138[0m [38;5;28;01mexcept[39;00m [38;5;167;01mKeyError[39;00m:
[0;32m--> 139[0m     [38;5;28;01mraise[39;00m [38;5;167;01mAttributeError[39;00m(
[1;32m    140[0m         [38;5;124mf[39m[38;5;124m"[39m[38;5;124mModule [39m[38;5;124m'[39m[38;5;124mscipy[39m[38;5;124m'[39m[38;5;124m has no attribute [39m[38;5;124m'[39m[38;5;132;01m{[39;00mname[38;5;132;01m}[39;00m[38;5;124m'[39m[38;5;124m"[39m
[1;32m    141[0m     )

[0;31mAttributeError[0m: Module 'scipy' has no attribute 'mean'

