Traceback (most recent call last):
  File "/mnt/home/rsilva/Documents/miniconda3/envs/bioestats/lib/python3.9/site-packages/jupyter_cache/executors/utils.py", line 58, in single_nb_execution
    executenb(
  File "/mnt/home/rsilva/Documents/miniconda3/envs/bioestats/lib/python3.9/site-packages/nbclient/client.py", line 1314, in execute
    return NotebookClient(nb=nb, resources=resources, km=km, **kwargs).execute()
  File "/mnt/home/rsilva/Documents/miniconda3/envs/bioestats/lib/python3.9/site-packages/jupyter_core/utils/__init__.py", line 165, in wrapped
    return loop.run_until_complete(inner)
  File "/mnt/home/rsilva/Documents/miniconda3/envs/bioestats/lib/python3.9/asyncio/base_events.py", line 647, in run_until_complete
    return future.result()
  File "/mnt/home/rsilva/Documents/miniconda3/envs/bioestats/lib/python3.9/site-packages/nbclient/client.py", line 709, in async_execute
    await self.async_execute_cell(
  File "/mnt/home/rsilva/Documents/miniconda3/envs/bioestats/lib/python3.9/site-packages/nbclient/client.py", line 1062, in async_execute_cell
    await self._check_raise_for_error(cell, cell_index, exec_reply)
  File "/mnt/home/rsilva/Documents/miniconda3/envs/bioestats/lib/python3.9/site-packages/nbclient/client.py", line 918, in _check_raise_for_error
    raise CellExecutionError.from_cell_and_msg(cell, exec_reply_content)
nbclient.exceptions.CellExecutionError: An error occurred while executing the following cell:
------------------
import pandas as pd
import numpy as np
from scipy import stats

gls = [13, 14, 15]
a05 = [round(-stats.t(x).ppf(0.05), 4) for x in gls]
a01 = [round(-stats.t(x).ppf(0.01), 4) for x in gls]

df = pd.DataFrame(zip(gls, a05, a01), columns=['gl', r'$\alpha = .05$', r'$\alpha = .01$'])

color = (df.iloc[:,1] == df.loc[1,r'$\alpha = .05$']).map({True: 'background-color: yellow', False: ''})

df.style.apply(lambda s: color)
------------------


[0;31m---------------------------------------------------------------------------[0m
[0;31mModuleNotFoundError[0m                       Traceback (most recent call last)
Cell [0;32mIn[1], line 3[0m
[1;32m      1[0m [38;5;28;01mimport[39;00m [38;5;21;01mpandas[39;00m [38;5;28;01mas[39;00m [38;5;21;01mpd[39;00m
[1;32m      2[0m [38;5;28;01mimport[39;00m [38;5;21;01mnumpy[39;00m [38;5;28;01mas[39;00m [38;5;21;01mnp[39;00m
[0;32m----> 3[0m [38;5;28;01mfrom[39;00m [38;5;21;01mscipy[39;00m [38;5;28;01mimport[39;00m stats
[1;32m      5[0m gls [38;5;241m=[39m [[38;5;241m13[39m, [38;5;241m14[39m, [38;5;241m15[39m]
[1;32m      6[0m a05 [38;5;241m=[39m [[38;5;28mround[39m([38;5;241m-[39mstats[38;5;241m.[39mt(x)[38;5;241m.[39mppf([38;5;241m0.05[39m), [38;5;241m4[39m) [38;5;28;01mfor[39;00m x [38;5;129;01min[39;00m gls]

[0;31mModuleNotFoundError[0m: No module named 'scipy'

